<?xml version="1.0" ?>
<robot name="gripperv4">

<material name="silver">
  <color rgba="0.700 0.700 0.700 1.000"/>
</material>

<link name="base_link">
  <inertial>
    <origin rpy="0 0 0" xyz="0.015992436485837883 -0.0949999999742469 -0.040090057637020185"/>
    <mass value="0.009061016616131982"/>
    <inertia ixx="2.917479451602619e-07" ixy="3.3607556841619424e-16" ixz="9.210836889043852e-12" iyy="2.9023880028295593e-07" iyz="-5.029139539709793e-16" izz="5.504267885101858e-07"/>
  </inertial>
  <visual>
    <origin rpy="0 0 0" xyz="0 0 0"/>
    <geometry>
      <mesh filename="meshes/base_link.stl" scale="0.001 0.001 0.001"/>
    </geometry>
    <material name="silver"/>
    <material/>
  </visual>
  <collision>
    <origin rpy="0 0 0" xyz="0 0 0"/>
    <geometry>
      <mesh filename="meshes/base_link.stl" scale="0.001 0.001 0.001"/>
    </geometry>
  </collision>
</link>

<link name="roll_yaw_servo1">
  <inertial>
    <origin rpy="0 0 0" xyz="-0.013268240030092209 0.016285248127358667 0.016124466822691624"/>
    <mass value="0.6469480906726006"/>
    <inertia ixx="0.0002746002016814908" ixy="1.6904286845290833e-06" ixz="-1.6916061051645942e-06" iyy="0.0001706247777873023" iyz="-2.7121799154343137e-06" izz="0.00034182155339970884"/>
  </inertial>
  <visual>
    <origin rpy="0 0 0" xyz="-0.016 0.095 0.0374"/>
    <geometry>
      <mesh filename="meshes/roll_yaw_servo1.stl" scale="0.001 0.001 0.001"/>
    </geometry>
    <material name="silver"/>
    <material/>
  </visual>
  <collision>
    <origin rpy="0 0 0" xyz="-0.016 0.095 0.0374"/>
    <geometry>
      <mesh filename="meshes/roll_yaw_servo1.stl" scale="0.001 0.001 0.001"/>
    </geometry>
  </collision>
</link>

<link name="gripper_mount1">
  <inertial>
    <origin rpy="0 0 0" xyz="-4.652947513627062e-05 0.03250495822449525 0.0008818441838164721"/>
    <mass value="0.6707222526282031"/>
    <inertia ixx="0.00019860440757462537" ixy="3.339203666162917e-08" ixz="-1.0677422396709792e-08" iyy="0.00028397193654952125" iyz="3.310663035340709e-06" izz="0.0003533390722831966"/>
  </inertial>
  <visual>
    <origin rpy="0 0 0" xyz="-0.016 0.0466 0.021"/>
    <geometry>
      <mesh filename="meshes/gripper_mount1.stl" scale="0.001 0.001 0.001"/>
    </geometry>
    <material name="silver"/>
    <material/>
  </visual>
  <collision>
    <origin rpy="0 0 0" xyz="-0.016 0.0466 0.021"/>
    <geometry>
      <mesh filename="meshes/gripper_mount1.stl" scale="0.001 0.001 0.001"/>
    </geometry>
  </collision>
</link>

<link name="l_link11">
  <inertial>
    <origin rpy="0 0 0" xyz="1.5906387325074444e-11 0.007497428337157438 -0.004836993401442812"/>
    <mass value="0.014672073181914151"/>
    <inertia ixx="7.718519171315755e-06" ixy="2.038407957350974e-15" ixz="-1.2067185530077512e-15" iyy="4.21228855882684e-06" iyz="1.1851915531991561e-06" izz="4.246963434879085e-06"/>
  </inertial>
  <visual>
    <origin rpy="0 0 0" xyz="-0.0 -0.0 0.0044"/>
    <geometry>
      <mesh filename="meshes/l_link11.stl" scale="0.001 0.001 0.001"/>
    </geometry>
    <material name="silver"/>
    <material/>
  </visual>
  <collision>
    <origin rpy="0 0 0" xyz="-0.0 -0.0 0.0044"/>
    <geometry>
      <mesh filename="meshes/l_link11.stl" scale="0.001 0.001 0.001"/>
    </geometry>
  </collision>
</link>

<link name="r_link11">
  <inertial>
    <origin rpy="0 0 0" xyz="-1.4336560688610334e-09 0.007497418801402903 -0.004836999106063676"/>
    <mass value="0.014672069251285016"/>
    <inertia ixx="7.718515084263593e-06" ixy="6.201971419677395e-13" ixz="2.8387697669439958e-14" iyy="4.212289771974431e-06" iyz="1.1851946665663398e-06" izz="4.246958318785204e-06"/>
  </inertial>
  <visual>
    <origin rpy="0 0 0" xyz="-0.032 -0.0 0.0044"/>
    <geometry>
      <mesh filename="meshes/r_link11.stl" scale="0.001 0.001 0.001"/>
    </geometry>
    <material name="silver"/>
    <material/>
  </visual>
  <collision>
    <origin rpy="0 0 0" xyz="-0.032 -0.0 0.0044"/>
    <geometry>
      <mesh filename="meshes/r_link11.stl" scale="0.001 0.001 0.001"/>
    </geometry>
  </collision>
</link>

<link name="l_link31">
  <inertial>
    <origin rpy="0 0 0" xyz="-0.0017956453296221562 0.02496942356962671 -0.018242185156636687"/>
    <mass value="0.027635011745384516"/>
    <inertia ixx="1.7261546453361967e-05" ixy="-1.913789502182194e-06" ixz="-4.1288871170401643e-07" iyy="3.610758696806827e-06" iyz="-1.2448919056449177e-06" izz="1.5583906769825435e-05"/>
  </inertial>
  <visual>
    <origin rpy="0 0 0" xyz="-0.0 -0.05 0.003"/>
    <geometry>
      <mesh filename="meshes/l_link31.stl" scale="0.001 0.001 0.001"/>
    </geometry>
    <material name="silver"/>
    <material/>
  </visual>
  <collision>
    <origin rpy="0 0 0" xyz="-0.0 -0.05 0.003"/>
    <geometry>
      <mesh filename="meshes/l_link31.stl" scale="0.001 0.001 0.001"/>
    </geometry>
  </collision>
</link>

<link name="r_link31">
  <inertial>
    <origin rpy="0 0 0" xyz="0.0017956453296221475 0.024969423569626725 -0.018242185156636687"/>
    <mass value="0.027635011745384488"/>
    <inertia ixx="1.726154645336045e-05" ixy="1.9137895021821837e-06" ixz="4.128887117040158e-07" iyy="3.6107586968067967e-06" iyz="-1.2448919056448838e-06" izz="1.558390676982397e-05"/>
  </inertial>
  <visual>
    <origin rpy="0 0 0" xyz="-0.032 -0.05 0.003"/>
    <geometry>
      <mesh filename="meshes/r_link31.stl" scale="0.001 0.001 0.001"/>
    </geometry>
    <material name="silver"/>
    <material/>
  </visual>
  <collision>
    <origin rpy="0 0 0" xyz="-0.032 -0.05 0.003"/>
    <geometry>
      <mesh filename="meshes/r_link31.stl" scale="0.001 0.001 0.001"/>
    </geometry>
  </collision>
</link>

<joint name="Rev_base" type="continuous">
  <origin rpy="0 0 0" xyz="0.016 -0.095 -0.0374"/>
  <parent link="base_link"/>
  <child link="roll_yaw_servo1"/>
  <axis xyz="0.0 0.0 1.0"/>
</joint>
<transmission name="Rev_base_tran">
  <type>transmission_interface/SimpleTransmission</type>
  <joint name="Rev_base">
    <hardwareInterface>PositionJointInterface</hardwareInterface>
  </joint>
  <actuator name="Rev_base_actr">
    <hardwareInterface>PositionJointInterface</hardwareInterface>
    <mechanicalReduction>1</mechanicalReduction>
  </actuator>
</transmission>

<joint name="Rev_roll" type="continuous">
  <origin rpy="0 0 0" xyz="0.0 0.0484 0.0164"/>
  <parent link="roll_yaw_servo1"/>
  <child link="gripper_mount1"/>
  <axis xyz="0.0 1.0 -0.0"/>
</joint>
<transmission name="Rev_roll_tran">
  <type>transmission_interface/SimpleTransmission</type>
  <joint name="Rev_roll">
    <hardwareInterface>PositionJointInterface</hardwareInterface>
  </joint>
  <actuator name="Rev_roll_actr">
    <hardwareInterface>PositionJointInterface</hardwareInterface>
    <mechanicalReduction>1</mechanicalReduction>
  </actuator>
</transmission>

<joint name="Rev_left" type="continuous">
  <origin rpy="0 0 0" xyz="-0.016 0.0466 0.0166"/>
  <parent link="gripper_mount1"/>
  <child link="l_link11"/>
  <axis xyz="0.0 0.0 1.0"/>
</joint>
<transmission name="Rev_left_tran">
  <type>transmission_interface/SimpleTransmission</type>
  <joint name="Rev_left">
    <hardwareInterface>PositionJointInterface</hardwareInterface>
  </joint>
  <actuator name="Rev_left_actr">
    <hardwareInterface>PositionJointInterface</hardwareInterface>
    <mechanicalReduction>1</mechanicalReduction>
  </actuator>
</transmission>

<joint name="Rev_right" type="continuous">
  <origin rpy="0 0 0" xyz="0.016 0.0466 0.0166"/>
  <parent link="gripper_mount1"/>
  <child link="r_link11"/>
  <axis xyz="0.0 0.0 1.0"/>
</joint>
<transmission name="Rev_right_tran">
  <type>transmission_interface/SimpleTransmission</type>
  <joint name="Rev_right">
    <hardwareInterface>PositionJointInterface</hardwareInterface>
  </joint>
  <actuator name="Rev_right_actr">
    <hardwareInterface>PositionJointInterface</hardwareInterface>
    <mechanicalReduction>1</mechanicalReduction>
  </actuator>
</transmission>

<joint name="Rev_left_finger" type="continuous">
  <origin rpy="0 0 0" xyz="0.0 0.05 0.0014"/>
  <parent link="l_link11"/>
  <child link="l_link31"/>
  <axis xyz="0.0 0.0 -1.0"/>
</joint>
<transmission name="Rev_left_finger_tran">
  <type>transmission_interface/SimpleTransmission</type>
  <joint name="Rev_left_finger">
    <hardwareInterface>PositionJointInterface</hardwareInterface>
  </joint>
  <actuator name="Rev_left_finger_actr">
    <hardwareInterface>PositionJointInterface</hardwareInterface>
    <mechanicalReduction>1</mechanicalReduction>
  </actuator>
</transmission>

<joint name="Rev_right_finger" type="continuous">
  <origin rpy="0 0 0" xyz="0.0 0.05 0.0014"/>
  <parent link="r_link11"/>
  <child link="r_link31"/>
  <axis xyz="0.0 0.0 1.0"/>
</joint>
<transmission name="Rev_right_finger_tran">
  <type>transmission_interface/SimpleTransmission</type>
  <joint name="Rev_right_finger">
    <hardwareInterface>PositionJointInterface</hardwareInterface>
  </joint>
  <actuator name="Rev_right_finger_actr">
    <hardwareInterface>PositionJointInterface</hardwareInterface>
    <mechanicalReduction>1</mechanicalReduction>
  </actuator>
</transmission>

</robot>
